<?xml version="1.0" ?>
<!--
  This is not a standalone urdf for kobuki. It simply defines the 'kobuki' tag that can
  be incorporated by other urdf files (e.g. turtlebot).

  See kobuki_standalone.urdf.xacro for a standalone urdf to be tested with
      kobuki_description/launch/view_model.launch
 -->
<robot name="kobuki" xmlns:xacro="http://ros.org/wiki/xacro">
  <xacro:include filename="$(find jaime_description)/urdf/common_properties.urdf.xacro"/>

  <!-- Kobuki -->
  <xacro:macro name="kobuki" params = "namespace">

    
    <link name="${namespace}base_link"> 
      <visual>
        <geometry>
          <!-- new mesh -->
          <mesh filename="file://$(find jaime_description)/meshes/main_body.dae" />
        </geometry>
        <origin xyz="0.001 0 0.05199" rpy="0 0 0"/>
      </visual>
      <collision name="base">
        <geometry>
          <cylinder length="0.10938" radius="0.178"/>
        </geometry>
        <origin xyz="0.0 0 0.05949" rpy="0 0 0"/>
      </collision>
      <inertial>
        <!-- COM experimentally determined -->
        <origin xyz="0.01 0 0"/>
        <mass value="2.4"/> <!-- 2.4/2.6 kg for small/big battery pack -->
        <!-- Kobuki's inertia tensor is approximated by a cylinder with homogeneous mass distribution
             More details http://en.wikipedia.org/wiki/List_of_moment_of_inertia_tensors
             m = 2.4 kg; h = 0.09 m; r = 0.175 m
             ixx = 1/12 * m * (3 * r^2 + h^2)
             iyy = 1/12 * m * (3 * r^2 + h^2)
             izz = 1/2 * m * r^2
          -->
        <inertia ixx="0.019995" ixy="0.0" ixz="0.0"
                 iyy="0.019995" iyz="0.0"
                 izz="0.03675" />
      </inertial>
    </link>

    <joint name="${namespace}wheel_left_joint" type="continuous">
      <parent link="${namespace}base_link"/>
      <child link="${namespace}wheel_left_link"/>
      <origin xyz="0.00 ${0.23/2} 0.0250" rpy="${-M_PI/2} 0 0"/>
      <axis xyz="0 0 1"/>
    </joint>
    <link name="${namespace}wheel_left_link">
      <visual>
        <geometry>
          <mesh filename="file://$(find jaime_description)/meshes/wheel.dae"/>
        </geometry>
        <origin xyz="0 0 0" rpy="0 0 0"/>
      </visual>
      <collision>
        <geometry>
          <cylinder length="0.0206" radius="0.035"/>
        </geometry>
        <origin rpy="0 0 0" xyz="0 0 0"/>
      </collision>
        <inertial>
        <mass value="0.01" />
        <origin xyz="0 0 0" />
        <inertia ixx="0.001" ixy="0.0" ixz="0.0"
                 iyy="0.001" iyz="0.0"
                 izz="0.001" />
      </inertial>
    </link>

    <joint name="${namespace}wheel_right_joint" type="continuous">
      <parent link="${namespace}base_link"/>
      <child link="${namespace}wheel_right_link"/>
      <origin xyz="0.00 -${0.23/2} 0.0250" rpy="${-M_PI/2} 0 0"/>
      <axis xyz="0 0 1"/>
    </joint>
    <link name="${namespace}wheel_right_link">
      <visual>
        <geometry>
          <mesh filename="file://$(find jaime_description)/meshes/wheel.dae"/>
        </geometry>
        <origin xyz="0 0 0" rpy="0 0 0"/>
      </visual>
      <collision>
        <geometry>
          <cylinder length="0.0206" radius="0.035"/>
        </geometry>
        <origin rpy="0 0 0" xyz="0 0 0"/>
      </collision>
      <inertial>
        <mass value="0.01" />
        <origin xyz="0 0 0" />
        <inertia ixx="0.001" ixy="0.0" ixz="0.0"
                 iyy="0.001" iyz="0.0"
                 izz="0.001" />
      </inertial>
    </link>

    <joint name="${namespace}caster_front_joint" type="fixed">
      <parent link="${namespace}base_link"/>
      <child link="${namespace}caster_front_link"/>
      <origin xyz="0.115 0.0 0.007" rpy="${-M_PI/2} 0 0"/>
    </joint>
    <link name="${namespace}caster_front_link">
      <collision>
        <geometry>
          <cylinder length="0.0176" radius="0.017"/>
        </geometry>
        <origin rpy="0 0 0" xyz="0 0 0"/>
      </collision>
      <inertial>
        <mass value="0.01" />
        <origin xyz="0 0 0" />
        <inertia ixx="0.001" ixy="0.0" ixz="0.0"
                 iyy="0.001" iyz="0.0"
                 izz="0.001" />
      </inertial>
    </link>

    <joint name="${namespace}caster_back_joint" type="fixed">
      <parent link="${namespace}base_link"/>
      <child link="${namespace}caster_back_link"/>
      <origin xyz="-0.135 0.0 0.009" rpy="${-M_PI/2} 0 0"/>
    </joint>
    <link name="${namespace}caster_back_link">
      <collision>
        <geometry>
          <cylinder length="0.0176" radius="0.017"/>
        </geometry>
        <origin rpy="0 0 0" xyz="0 0 0"/>
      </collision>
      <inertial>
        <mass value="0.01" />
        <origin xyz="0 0 0" />
        <inertia ixx="0.001" ixy="0.0" ixz="0.0"
                 iyy="0.001" iyz="0.0"
                 izz="0.001" />
      </inertial>
    </link>

    <!-- Kobuki's sensors -->
    <joint name="${namespace}gyro_joint" type="fixed">
  <parent link="${namespace}base_link"/>
  <child link="${namespace}gyro_link"/>
  <origin xyz="0.056 0.062 0.0202" rpy="0 0 0"/>
  <axis xyz="0 1 0"/>
</joint>

<link name="${namespace}gyro_link">
  <inertial>
    <mass value="0.001"/>
    <origin xyz="0 0 0" rpy="0 0 0"/>
    <inertia ixx="0.0001" ixy="0" ixz="0"
             iyy="0.000001" iyz="0"
             izz="0.0001"/>
  </inertial>
</link>

    <joint name="${namespace}cliff_sensor_left_joint" type="fixed">
      <origin xyz="0.08734 0.13601 0.0214" rpy="0 ${M_PI/2} 0" />
      <parent link="${namespace}base_link"/>
      <child link="${namespace}cliff_sensor_left_link" />
    </joint>
    <link name="${namespace}cliff_sensor_left_link">
      <inertial>
        <mass value="0.0001" />
        <origin xyz="0 0 0" />
        <inertia ixx="0.0001" ixy="0.0" ixz="0.0"
                 iyy="0.0001" iyz="0.0"
                 izz="0.0001" />
      </inertial>
    </link>

    <joint name="${namespace}cliff_sensor_right_joint" type="fixed">
      <origin xyz="0.085 -0.13601 0.0214" rpy="0 ${M_PI/2} 0" />
      <parent link="${namespace}base_link"/>
      <child link="${namespace}cliff_sensor_right_link" />
    </joint>
    <link name="${namespace}cliff_sensor_right_link">
      <inertial>
        <mass value="0.0001" />
        <origin xyz="0 0 0" />
        <inertia ixx="0.0001" ixy="0.0" ixz="0.0"
                 iyy="0.0001" iyz="0.0"
                 izz="0.0001" />
      </inertial>
    </link>

    <joint name="${namespace}cliff_sensor_front_joint" type="fixed">
      <origin xyz="0.156 0.00 0.0214" rpy="0 ${M_PI/2} 0" />
      <parent link="${namespace}base_link"/>
      <child link="${namespace}cliff_sensor_front_link" />
    </joint>
    <link name="${namespace}cliff_sensor_front_link">
      <inertial>
        <mass value="0.0001" />
        <origin xyz="0 0 0" />
        <inertia ixx="0.0001" ixy="0.0" ixz="0.0"
                 iyy="0.0001" iyz="0.0"
                 izz="0.0001" />
      </inertial>
    </link>

  </xacro:macro>
</robot>
